Workbook

Sheet Leia-me
A1: Como usar esta planilha
A3: REGRA DE ENTRADA (o que conta como jogo zeravel)
A4: Entra: campanha, capitulos ou historia com creditos finais.
A5: Fica de fora: roguelike/roguelite, online competitivo, PvP, live service e sandbox sem fim.
A7: AS ABAS
A8: Catalogo ............. lista mestre. E o unico lugar onde voce marca progresso.
A9: Plano mensal ......... a rotina: 2 jogos por mes, gerada automaticamente do
A10: catalogo inteiro, ordenada da menor pra maior duracao.
A11: Painel ............... contadores automaticos de progresso.
A12: Fora do escopo ....... o que foi cortado e por que (roguelike/online/PvP/sandbox).
A13: Nao classificados .... jogos obscuros que eu nao conhecia o suficiente pra decidir;
A14: preencha a coluna e mova pra aba certa.
... A48: Jogos fora do escopo continuam jogaveis - so nao entram na contagem de zerados.

Sheet Catalogo
A1: Catalogo de jogos zeraveis - biblioteca Steam Family
A2: Preencha apenas as colunas em amarelo (Status, Zerado em, Nota). As demais alimentam o Plano e o Painel.
A4: Jogo | B4: Nivel | C4: Faixa | D4: Horas est. | E4: Genero | F4: Por que e zeravel | G4: Status | H4: Zerado em | I4: Nota (0-10)
A5: EXEMPLO - apague esta linha | B5: 1 | C5: Nivel 1 - Aperitivo (ate 5h) | D5: 3 | E5: Puzzle | F5: Campanha curta | G5: Zerado | H5: 2026-08-15 | I5: 9
A6: Overcooked! (1 e 2) | B6: 1 | C6: Nivel 1 - Aperitivo (ate 5h) | D6: 8 | E6: Co-op / gerência | F6: Fases fixas com final | G6: Nao iniciado
A7: Jump King | B7: 1 | C7: Nivel 1 - Aperitivo (ate 5h) | D7: 5 | E7: Plataforma | F7: Topo fixo = final do jogo | G7: Nao iniciado
A8: Little Nightmares | B8: 1 | C8: Nivel 1 - Aperitivo (ate 5h) | D8: 5 | E8: Terror-puzzle | F8: Campanha linear com final | G8: Nao iniciado
A9: Momodora: Reverie Under the Moonlight | B9: 1 | C9: Nivel 1 - Aperitivo (ate 5h) | D9: 5 | E9: Metroidvania | F9: Mapa fixo, final definido | G9: Nao iniciado
A10: Neva | B10: 1 | C10: Nivel 1 - Aperitivo (ate 5h) | D10: 5 | E10: Aventura narrativa | F10: Campanha linear com final | G10: Nao iniciado
A11: Reventure | B11: 1 | C11: Nivel 1 - Aperitivo (ate 5h) | D11: 5 | E11: Aventura | F11: Finais colecionáveis, escopo fechado | G11: Nao iniciado
A12: Terra Nil | B12: 1 | C12: Nivel 1 - Aperitivo (ate 5h) | D12: 5 | E12: Estratégia / puzzle | F12: Cada mapa tem final definido | G12: Nao iniciado
A13: Titan Souls | B13: 1 | C13: Nivel 1 - Aperitivo (ate 5h) | D13: 5 | E13: Ação / boss rush | F13: Número fixo de chefes | G13: Nao iniciado
A14: Totally Reliable Delivery Service | B14: 1 | C14: Nivel 1 - Aperitivo (ate 5h) | D14: 5 | E14: Sandbox físico co-op | F14: Missões fixas com final | G14: Nao iniciado
A15: Biped | B15: 1 | C15: Nivel 1 - Aperitivo (ate 5h) | D15: 4 | E15: Plataforma co-op | F15: Campanha de fases fixas | G15: Nao iniciado
A16: Castle of Illusion | B16: 1 | C16: Nivel 1 - Aperitivo (ate 5h) | D16: 4 | E16: Plataforma | F16: Fases fixas até o final | G16: Nao iniciado
A17: Eets | B17: 1 | C17: Nivel 1 - Aperitivo (ate 5h) | D17: 4 | E17: Puzzle-plataforma | F17: Fases fixas com final | G17: Nao iniciado
... A156: DARK SOULS III | B156: 5 | C156: Nivel 5 - Maratona (46h+) | D156: 46 | E156: RPG de ação | F156: Campanha com final | G156: Nao iniciado
A158: Horas estimadas = campanha principal, ordem de grandeza (referencia HowLongToBeat). Ajuste livremente.

Sheet Plano mensal
A1: Rotina de zeramento - 2 jogos por mes, do mais leve ao mais denso
A2: Um mes = um jogo curto + um mais longo. O Status vem do Catalogo automaticamente; edite so a coluna Mes/ano se quiser fixar datas.
A4: Mes | B4: Fase | C4: Mes/ano | D4: Jogo | E4: Nivel | F4: Horas est. | G4: Status | H4: Horas do mes
A5: 1 | B5: Fase 1 - Aquecimento | D5: The Dark Queen of Mortholme | E5: =INDEX(Catalogo!$B$6:$B$156,MATCH($D5,Catalogo!$A$6:$A$156,0)) -> 1 | F5: =INDEX(Catalogo!$D$6:$D$156,MATCH($D5,Catalogo!$A$6:$A$156,0)) -> 1 | G5: =INDEX(Catalogo!$G$6:$G$156,MATCH($D5,Catalogo!$A$6:$A$156,0)) -> Nao iniciado | H5: =SUM(F5:F6) -> 3
D6: Buckshot Roulette | E6: =INDEX(Catalogo!$B$6:$B$156,MATCH($D6,Catalogo!$A$6:$A$156,0)) -> 1 | F6: =INDEX(Catalogo!$D$6:$D$156,MATCH($D6,Catalogo!$A$6:$A$156,0)) -> 2 | G6: =INDEX(Catalogo!$G$6:$G$156,MATCH($D6,Catalogo!$A$6:$A$156,0)) -> Nao iniciado
A7: 2 | B7: Fase 1 - Aquecimento | D7: Journey | E7: =INDEX(Catalogo!$B$6:$B$156,MATCH($D7,Catalogo!$A$6:$A$156,0)) -> 1 | F7: =INDEX(Catalogo!$D$6:$D$156,MATCH($D7,Catalogo!$A$6:$A$156,0)) -> 2 | G7: =INDEX(Catalogo!$G$6:$G$156,MATCH($D7,Catalogo!$A$6:$A$156,0)) -> Nao iniciado | H7: =SUM(F7:F8) -> 4
D8: Just Ignore Them | E8: =INDEX(Catalogo!$B$6:$B$156,MATCH($D8,Catalogo!$A$6:$A$156,0)) -> 1 | F8: =INDEX(Catalogo!$D$6:$D$156,MATCH($D8,Catalogo!$A$6:$A$156,0)) -> 2 | G8: =INDEX(Catalogo!$G$6:$G$156,MATCH($D8,Catalogo!$A$6:$A$156,0)) -> Nao iniciado
A9: 3 | B9: Fase 1 - Aquecimento | D9: KinitoPET | E9: =INDEX(Catalogo!$B$6:$B$156,MATCH($D9,Catalogo!$A$6:$A$156,0)) -> 1 | F9: =INDEX(Catalogo!$D$6:$D$156,MATCH($D9,Catalogo!$A$6:$A$156,0)) -> 2 | G9: =INDEX(Catalogo!$G$6:$G$156,MATCH($D9,Catalogo!$A$6:$A$156,0)) -> Nao iniciado | H9: =SUM(F9:F10) -> 4
D10: The Deed | E10: =INDEX(Catalogo!$B$6:$B$156,MATCH($D10,Catalogo!$A$6:$A$156,0)) -> 1 | F10: =INDEX(Catalogo!$D$6:$D$156,MATCH($D10,Catalogo!$A$6:$A$156,0)) -> 2 | G10: =INDEX(Catalogo!$G$6:$G$156,MATCH($D10,Catalogo!$A$6:$A$156,0)) -> Nao iniciado
A11: 4 | B11: Fase 1 - Aquecimento | D11: Five Nights at Freddy's (série) | E11: =INDEX(Catalogo!$B$6:$B$156,MATCH($D11,Catalogo!$A$6:$A$156,0)) -> 1 | F11: =INDEX(Catalogo!$D$6:$D$156,MATCH($D11,Catalogo!$A$6:$A$156,0)) -> 3 | G11: =INDEX(Catalogo!$G$6:$G$156,MATCH($D11,Catalogo!$A$6:$A$156,0)) -> Nao iniciado | H11: =SUM(F11:F12) -> 6
D12: Journey of a Roach | E12: =INDEX(Catalogo!$B$6:$B$156,MATCH($D12,Catalogo!$A$6:$A$156,0)) -> 1 | F12: =INDEX(Catalogo!$D$6:$D$156,MATCH($D12,Catalogo!$A$6:$A$156,0)) -> 3 | G12: =INDEX(Catalogo!$G$6:$G$156,MATCH($D12,Catalogo!$A$6:$A$156,0)) -> Nao iniciado
A13: 5 | B13: Fase 1 - Aquecimento | D13: Portal | E13: =INDEX(Catalogo!$B$6:$B$156,MATCH($D13,Catalogo!$A$6:$A$156,0)) -> 1 | F13: =INDEX(Catalogo!$D$6:$D$156,MATCH($D13,Catalogo!$A$6:$A$156,0)) -> 3 | G13: =INDEX(Catalogo!$G$6:$G$156,MATCH($D13,Catalogo!$A$6:$A$156,0)) -> Nao iniciado | H13: =SUM(F13:F14) -> 6
D14: The Red Lantern | E14: =INDEX(Catalogo!$B$6:$B$156,MATCH($D14,Catalogo!$A$6:$A$156,0)) -> 1 | F14: =INDEX(Catalogo!$D$6:$D$156,MATCH($D14,Catalogo!$A$6:$A$156,0)) -> 3 | G14: =INDEX(Catalogo!$G$6:$G$156,MATCH($D14,Catalogo!$A$6:$A$156,0)) -> Nao iniciado
A15: 6 | B15: Fase 1 - Aquecimento | D15: Uncanny Tales: Cold Road | E15: =INDEX(Catalogo!$B$6:$B$156,MATCH($D15,Catalogo!$A$6:$A$156,0)) -> 1 | F15: =INDEX(Catalogo!$D$6:$D$156,MATCH($D15,Catalogo!$A$6:$A$156,0)) -> 3 | G15: =INDEX(Catalogo!$G$6:$G$156,MATCH($D15,Catalogo!$A$6:$A$156,0)) -> Nao iniciado | H15: =SUM(F15:F16) -> 7
D16: Biped | E16: =INDEX(Catalogo!$B$6:$B$156,MATCH($D16,Catalogo!$A$6:$A$156,0)) -> 1 | F16: =INDEX(Catalogo!$D$6:$D$156,MATCH($D16,Catalogo!$A$6:$A$156,0)) -> 4 | G16: =INDEX(Catalogo!$G$6:$G$156,MATCH($D16,Catalogo!$A$6:$A$156,0)) -> Nao iniciado
A17: 7 | B17: Fase 1 - Aquecimento | D17: Castle of Illusion | E17: =INDEX(Catalogo!$B$6:$B$156,MATCH($D17,Catalogo!$A$6:$A$156,0)) -> 1 | F17: =INDEX(Catalogo!$D$6:$D$156,MATCH($D17,Catalogo!$A$6:$A$156,0)) -> 4 | G17: =INDEX(Catalogo!$G$6:$G$156,MATCH($D17,Catalogo!$A$6:$A$156,0)) -> Nao iniciado | H17: =SUM(F17:F18) -> 8
D18: Eets | E18: =INDEX(Catalogo!$B$6:$B$156,MATCH($D18,Catalogo!$A$6:$A$156,0)) -> 1 | F18: =INDEX(Catalogo!$D$6:$D$156,MATCH($D18,Catalogo!$A$6:$A$156,0)) -> 4 | G18: =INDEX(Catalogo!$G$6:$G$156,MATCH($D18,Catalogo!$A$6:$A$156,0)) -> Nao iniciado
A19: 8 | B19: Fase 1 - Aquecimento | D19: GRIS | E19: =INDEX(Catalogo!$B$6:$B$156,MATCH($D19,Catalogo!$A$6:$A$156,0)) -> 1 | F19: =INDEX(Catalogo!$D$6:$D$156,MATCH($D19,Catalogo!$A$6:$A$156,0)) -> 4 | G19: =INDEX(Catalogo!$G$6:$G$156,MATCH($D19,Catalogo!$A$6:$A$156,0)) -> Nao iniciado | H19: =SUM(F19:F20) -> 8
D20: Happy's Humble Burger Farm | E20: =INDEX(Catalogo!$B$6:$B$156,MATCH($D20,Catalogo!$A$6:$A$156,0)) -> 1 | F20: =INDEX(Catalogo!$D$6:$D$156,MATCH($D20,Catalogo!$A$6:$A$156,0)) -> 4 | G20: =INDEX(Catalogo!$G$6:$G$156,MATCH($D20,Catalogo!$A$6:$A$156,0)) -> Nao iniciado
A21: 9 | B21: Fase 1 - Aquecimento | D21: LIMBO | E21: =INDEX(Catalogo!$B$6:$B$156,MATCH($D21,Catalogo!$A$6:$A$156,0)) -> 1 | F21: =INDEX(Catalogo!$D$6:$D$156,MATCH($D21,Catalogo!$A$6:$A$156,0)) -> 4 | G21: =INDEX(Catalogo!$G$6:$G$156,MATCH($D21,Catalogo!$A$6:$A$156,0)) -> Nao iniciado | H21: =SUM(F21:F22) -> 8
D22: No, I'm not a Human | E22: =INDEX(Catalogo!$B$6:$B$156,MATCH($D22,Catalogo!$A$6:$A$156,0)) -> 1 | F22: =INDEX(Catalogo!$D$6:$D$156,MATCH($D22,Catalogo!$A$6:$A$156,0)) -> 4 | G22: =INDEX(Catalogo!$G$6:$G$156,MATCH($D22,Catalogo!$A$6:$A$156,0)) -> Nao iniciado
A23: 10 | B23: Fase 1 - Aquecimento | D23: Nosferatu: The Wrath of Malachi | E23: =INDEX(Catalogo!$B$6:$B$156,MATCH($D23,Catalogo!$A$6:$A$156,0)) -> 1 | F23: =INDEX(Catalogo!$D$6:$D$156,MATCH($D23,Catalogo!$A$6:$A$156,0)) -> 4 | G23: =INDEX(Catalogo!$G$6:$G$156,MATCH($D23,Catalogo!$A$6:$A$156,0)) -> Nao iniciado | H23: =SUM(F23:F24) -> 8
D24: Poppy Playtime | E24: =INDEX(Catalogo!$B$6:$B$156,MATCH($D24,Catalogo!$A$6:$A$156,0)) -> 1 | F24: =INDEX(Catalogo!$D$6:$D$156,MATCH($D24,Catalogo!$A$6:$A$156,0)) -> 4 | G24: =INDEX(Catalogo!$G$6:$G$156,MATCH($D24,Catalogo!$A$6:$A$156,0)) -> Nao iniciado
A25: 11 | B25: Fase 1 - Aquecimento | D25: That's not my Neighbor | E25: =INDEX(Catalogo!$B$6:$B$156,MATCH($D25,Catalogo!$A$6:$A$156,0)) -> 1 | F25: =INDEX(Catalogo!$D$6:$D$156,MATCH($D25,Catalogo!$A$6:$A$156,0)) -> 4 | G25: =INDEX(Catalogo!$G$6:$G$156,MATCH($D25,Catalogo!$A$6:$A$156,0)) -> Nao iniciado | H25: =SUM(F25:F26) -> 8
D26: The Room | E26: =INDEX(Catalogo!$B$6:$B$156,MATCH($D26,Catalogo!$A$6:$A$156,0)) -> 1 | F26: =INDEX(Catalogo!$D$6:$D$156,MATCH($D26,Catalogo!$A$6:$A$156,0)) -> 4 | G26: =INDEX(Catalogo!$G$6:$G$156,MATCH($D26,Catalogo!$A$6:$A$156,0)) -> Nao iniciado
A27: 12 | B27: Fase 1 - Aquecimento | D27: The Room Two | E27: =INDEX(Catalogo!$B$6:$B$156,MATCH($D27,Catalogo!$A$6:$A$156,0)) -> 1 | F27: =INDEX(Catalogo!$D$6:$D$156,MATCH($D27,Catalogo!$A$6:$A$156,0)) -> 4 | G27: =INDEX(Catalogo!$G$6:$G$156,MATCH($D27,Catalogo!$A$6:$A$156,0)) -> Nao iniciado | H27: =SUM(F27:F28) -> 8
D28: Violent Horror Stories: anthology | E28: =INDEX(Catalogo!$B$6:$B$156,MATCH($D28,Catalogo!$A$6:$A$156,0)) -> 1 | F28: =INDEX(Catalogo!$D$6:$D$156,MATCH($D28,Catalogo!$A$6:$A$156,0)) -> 4 | G28: =INDEX(Catalogo!$G$6:$G$156,MATCH($D28,Catalogo!$A$6:$A$156,0)) -> Nao iniciado
A29: 13 | B29: Fase 1 - Aquecimento | D29: Jump King | E29: =INDEX(Catalogo!$B$6:$B$156,MATCH($D29,Catalogo!$A$6:$A$156,0)) -> 1 | F29: =INDEX(Catalogo!$D$6:$D$156,MATCH($D29,Catalogo!$A$6:$A$156,0)) -> 5 | G29: =INDEX(Catalogo!$G$6:$G$156,MATCH($D29,Catalogo!$A$6:$A$156,0)) -> Nao iniciado | H29: =SUM(F29:F30) -> 10
D30: Little Nightmares | E30: =INDEX(Catalogo!$B$6:$B$156,MATCH($D30,Catalogo!$A$6:$A$156,0)) -> 1 | F30: =INDEX(Catalogo!$D$6:$D$156,MATCH($D30,Catalogo!$A$6:$A$156,0)) -> 5 | G30: =INDEX(Catalogo!$G$6:$G$156,MATCH($D30,Catalogo!$A$6:$A$156,0)) -> Nao iniciado
A31: 14 | B31: Fase 1 - Aquecimento | D31: Momodora: Reverie Under the Moonlight | E31: =INDEX(Catalogo!$B$6:$B$156,MATCH($D31,Catalogo!$A$6:$A$156,0)) -> 1 | F31: =INDEX(Catalogo!$D$6:$D$156,MATCH($D31,Catalogo!$A$6:$A$156,0)) -> 5 | G31: =INDEX(Catalogo!$G$6:$G$156,MATCH($D31,Catalogo!$A$6:$A$156,0)) -> Nao iniciado | H31: =SUM(F31:F32) -> 10
D32: Neva | E32: =INDEX(Catalogo!$B$6:$B$156,MATCH($D32,Catalogo!$A$6:$A$156,0)) -> 1 | F32: =INDEX(Catalogo!$D$6:$D$156,MATCH($D32,Catalogo!$A$6:$A$156,0)) -> 5 | G32: =INDEX(Catalogo!$G$6:$G$156,MATCH($D32,Catalogo!$A$6:$A$156,0)) -> Nao iniciado
A33: 15 | B33: Fase 1 - Aquecimento | D33: Reventure | E33: =INDEX(Catalogo!$B$6:$B$156,MATCH($D33,Catalogo!$A$6:$A$156,0)) -> 1 | F33: =INDEX(Catalogo!$D$6:$D$156,MATCH($D33,Catalogo!$A$6:$A$156,0)) -> 5 | G33: =INDEX(Catalogo!$G$6:$G$156,MATCH($D33,Catalogo!$A$6:$A$156,0)) -> Nao iniciado | H33: =SUM(F33:F34) -> 10
D34: Terra Nil | E34: =INDEX(Catalogo!$B$6:$B$156,MATCH($D34,Catalogo!$A$6:$A$156,0)) -> 1 | F34: =INDEX(Catalogo!$D$6:$D$156,MATCH($D34,Catalogo!$A$6:$A$156,0)) -> 5 | G34: =INDEX(Catalogo!$G$6:$G$156,MATCH($D34,Catalogo!$A$6:$A$156,0)) -> Nao iniciado
A35: 16 | B35: Fase 1 - Aquecimento | D35: Titan Souls | E35: =INDEX(Catalogo!$B$6:$B$156,MATCH($D35,Catalogo!$A$6:$A$156,0)) -> 1 | F35: =INDEX(Catalogo!$D$6:$D$156,MATCH($D35,Catalogo!$A$6:$A$156,0)) -> 5 | G35: =INDEX(Catalogo!$G$6:$G$156,MATCH($D35,Catalogo!$A$6:$A$156,0)) -> Nao iniciado | H35: =SUM(F35:F36) -> 10
D36: Totally Reliable Delivery Service | E36: =INDEX(Catalogo!$B$6:$B$156,MATCH($D36,Catalogo!$A$6:$A$156,0)) -> 1 | F36: =INDEX(Catalogo!$D$6:$D$156,MATCH($D36,Catalogo!$A$6:$A$156,0)) -> 5 | G36: =INDEX(Catalogo!$G$6:$G$156,MATCH($D36,Catalogo!$A$6:$A$156,0)) -> Nao iniciado
A37: 17 | B37: Fase 1 - Aquecimento | D37: Besiege | E37: =INDEX(Catalogo!$B$6:$B$156,MATCH($D37,Catalogo!$A$6:$A$156,0)) -> 2 | F37: =INDEX(Catalogo!$D$6:$D$156,MATCH($D37,Catalogo!$A$6:$A$156,0)) -> 6 | G37: =INDEX(Catalogo!$G$6:$G$156,MATCH($D37,Catalogo!$A$6:$A$156,0)) -> Nao iniciado | H37: =SUM(F37:F38) -> 12
D38: CARRION | E38: =INDEX(Catalogo!$B$6:$B$156,MATCH($D38,Catalogo!$A$6:$A$156,0)) -> 2 | F38: =INDEX(Catalogo!$D$6:$D$156,MATCH($D38,Catalogo!$A$6:$A$156,0)) -> 6 | G38: =INDEX(Catalogo!$G$6:$G$156,MATCH($D38,Catalogo!$A$6:$A$156,0)) -> Nao iniciado
A39: 18 | B39: Fase 1 - Aquecimento | D39: Call of Duty: Modern Warfare 2 (2009) | E39: =INDEX(Catalogo!$B$6:$B$156,MATCH($D39,Catalogo!$A$6:$A$156,0)) -> 2 | F39: =INDEX(Catalogo!$D$6:$D$156,MATCH($D39,Catalogo!$A$6:$A$156,0)) -> 6 | G39: =INDEX(Catalogo!$G$6:$G$156,MATCH($D39,Catalogo!$A$6:$A$156,0)) -> Nao iniciado | H39: =SUM(F39:F40) -> 12
D40: Call of Juarez Gunslinger | E40: =INDEX(Catalogo!$B$6:$B$156,MATCH($D40,Catalogo!$A$6:$A$156,0)) -> 2 | F40: =INDEX(Catalogo!$D$6:$D$156,MATCH($D40,Catalogo!$A$6:$A$156,0)) -> 6 | G40: =INDEX(Catalogo!$G$6:$G$156,MATCH($D40,Catalogo!$A$6:$A$156,0)) -> Nao iniciado
A41: 19 | B41: Fase 1 - Aquecimento | D41: Killer Frequency | E41: =INDEX(Catalogo!$B$6:$B$156,MATCH($D41,Catalogo!$A$6:$A$156,0)) -> 2 | F41: =INDEX(Catalogo!$D$6:$D$156,MATCH($D41,Catalogo!$A$6:$A$156,0)) -> 6 | G41: =INDEX(Catalogo!$G$6:$G$156,MATCH($D41,Catalogo!$A$6:$A$156,0)) -> Nao iniciado | H41: =SUM(F41:F42) -> 12
...

Sheet Painel
A1: Painel de progresso
A3: Resumo geral
A4: Jogos no catalogo | B4: =COUNTA(Catalogo!$A$6:$A$156) -> 151
A5: Zerados | B5: =COUNTIF(Catalogo!$G$6:$G$156,"Zerado") -> 0
A6: Jogando agora | B6: =COUNTIF(Catalogo!$G$6:$G$156,"Jogando") -> 0
A7: Abandonados | B7: =COUNTIF(Catalogo!$G$6:$G$156,"Abandonado") -> 0
A8: Nao iniciados | B8: =COUNTIF(Catalogo!$G$6:$G$156,"Nao iniciado") -> 151
A9: % concluido | B9: =IFERROR(B5/B4,0) -> 0
A10: Horas totais do catalogo | B10: =SUM(Catalogo!$D$6:$D$156) -> 2065
A11: Horas ja zeradas | B11: =SUMIF(Catalogo!$G$6:$G$156,"Zerado",Catalogo!$D$6:$D$156) -> 0
A12: Horas restantes | B12: =B10-B11 -> 2065
A14: Por nivel
A15: Nivel | B15: Total | C15: Zerados | D15: % do nivel | E15: Horas restantes
A16: Nivel 1 - Aperitivo (ate 5h) | B16: =COUNTIF(Catalogo!$B$6:$B$156,1) -> 33 | C16: =COUNTIFS(Catalogo!$B$6:$B$156,1,Catalogo!$G$6:$G$156,"Zerado") -> 0 | D16: =IFERROR(C16/B16,0) -> 0 | E16: =SUMIFS(Catalogo!$D$6:$D$156,Catalogo!$B$6:$B$156,1,Catalogo!$G$6:$G$156,"<>Zerado") -> 126
A17: Nivel 2 - Leve (6-12h) | B17: =COUNTIF(Catalogo!$B$6:$B$156,2) -> 55 | C17: =COUNTIFS(Catalogo!$B$6:$B$156,2,Catalogo!$G$6:$G$156,"Zerado") -> 0 | D17: =IFERROR(C17/B17,0) -> 0 | E17: =SUMIFS(Catalogo!$D$6:$D$156,Catalogo!$B$6:$B$156,2,Catalogo!$G$6:$G$156,"<>Zerado") -> 470
A18: Nivel 3 - Medio (13-25h) | B18: =COUNTIF(Catalogo!$B$6:$B$156,3) -> 41 | C18: =COUNTIFS(Catalogo!$B$6:$B$156,3,Catalogo!$G$6:$G$156,"Zerado") -> 0 | D18: =IFERROR(C18/B18,0) -> 0 | E18: =SUMIFS(Catalogo!$D$6:$D$156,Catalogo!$B$6:$B$156,3,Catalogo!$G$6:$G$156,"<>Zerado") -> 633
A19: Nivel 4 - Denso (26-45h) | B19: =COUNTIF(Catalogo!$B$6:$B$156,4) -> 15 | C19: =COUNTIFS(Catalogo!$B$6:$B$156,4,Catalogo!$G$6:$G$156,"Zerado") -> 0 | D19: =IFERROR(C19/B19,0) -> 0 | E19: =SUMIFS(Catalogo!$D$6:$D$156,Catalogo!$B$6:$B$156,4,Catalogo!$G$6:$G$156,"<>Zerado") -> 470
A20: Nivel 5 - Maratona (46h+) | B20: =COUNTIF(Catalogo!$B$6:$B$156,5) -> 7 | C20: =COUNTIFS(Catalogo!$B$6:$B$156,5,Catalogo!$G$6:$G$156,"Zerado") -> 0 | D20: =IFERROR(C20/B20,0) -> 0 | E20: =SUMIFS(Catalogo!$D$6:$D$156,Catalogo!$B$6:$B$156,5,Catalogo!$G$6:$G$156,"<>Zerado") -> 366
A21: TOTAL | B21: =SUM(B16:B20) -> 151 | C21: =SUM(C16:C20) -> 0 | D21: =IFERROR(C21/B21,0) -> 0 | E21: =SUM(E16:E20) -> 2065
A24: Meta: 2 jogos zerados por mes. No ritmo do plano, o catalogo inteiro leva ~76 meses.

Sheet Fora do escopo
A1: Jogos deixados de fora (sem fim definido)
A2: Roguelikes, online/PvP, live service e sandbox: nao ha o que zerar.
A4: Jogo / grupo | B4: Motivo
A5: Counter-Strike 2 | B5: Online competitivo / PvP - sem fim
A6: Dota 2 | B6: MOBA online / PvP - sem fim
A7: PUBG: BATTLEGROUNDS | B7: Battle royale online / PvP - sem fim
A8: Rust | B8: Survival online / PvP - sem fim
A9: DayZ | B9: Survival online / PvP - sem fim
A10: Dead by Daylight | B10: Multiplayer assimetrico / PvP - sem fim
A11: Destiny 2 | B11: Live service - conteudo continuo
A12: Path of Exile / Path of Exile 2 | B12: ARPG de temporadas - sem fim
A13: Sea of Thieves | B13: Mundo persistente online - sem fim
A14: Delta Force | B14: Tiro online / PvP - sem fim
A15: Brawlhalla | B15: Luta online / PvP - sem fim
... A164: Zomborg | B164: Roguelike - runs infinitas provavel

Sheet Nao classificados
A1: Titulos que eu nao consegui classificar com seguranca
A2: Sao jogos obscuros/indies que nao reconheco o suficiente para dizer se tem fim definido ou sao infinitos. Nao entraram no Catalogo nem em Fora do escopo para nao arriscar um chute errado. Classifique manualmente e mova para a aba certa.
A4: Jogo | B4: Sua classificacao (preencher)
A5: 171
A6: Aeonic
A7: 8AM
A8: Billies Wheelie
A9: Book of Spells 2
A10: Bunny Guys!
A11: Bunny Hurling
A12: Catch Me!
A13: Chip
A14: Coralina
A15: Dead Bits
A16: DeadPoly
... A55: Zueirama
